<?xml version="1.0" ?>
<!-- Generated using onshape-to-robot -->
<!-- Onshape document_id: 501d71139804d6d2b6e00194 -->
<robot name="mbf">
  <link name="base_link"></link>
  <joint name="base_link_joint" type="fixed">
    <parent link="base_link"/>
    <child link="chassis"/>
  </joint>
  <link name="imu_link"></link>
  <joint name="imu_joint" type="fixed">
    <parent link="chassis"/>
    <child link="imu_link"/>
  </joint>
  <!-- Link chassis -->
  <link name="chassis">
    <inertial>
      <origin xyz="0.00019173 0.000440232 -0.00216668" rpy="0 0 0"/>
      <mass value="2"/>
      <inertia ixx="0.00952998" ixy="3.50636e-05" ixz="-7.94274e-07" iyy="0.0135426" iyz="-1.90769e-06" izz="0.0186649"/>
    </inertial>
    <!-- Part chassis -->
    <visual>
      <origin xyz="0 0 0" rpy="0 -0 0"/>
      <geometry>
        <mesh filename="file://$(find mbf_description)/meshes/chassis.stl"/>
      </geometry>
      <material name="chassis_material">
        <color rgba="0.615686 0.811765 0.929412 1"/>
      </material>
    </visual>
    <collision>
      <origin xyz="0 0 0" rpy="0 -0 0"/>
      <geometry>
        <mesh filename="file://$(find mbf_description)/meshes/chassis.stl"/>
      </geometry>
    </collision>
  </link>
  <!-- Link shoulder -->
  <link name="fl_shoulder_link">
    <inertial>
      <origin xyz="-0.00572995 0.00737753 -1.10852e-06" rpy="0 0 0"/>
      <mass value="0.4"/>
      <inertia ixx="0.000212246" ixy="-1.68406e-05" ixz="-1.402e-08" iyy="0.000383001" iyz="-2.6453e-08" izz="0.000318608"/>
    </inertial>
    <!-- Part shoulder -->
    <visual>
      <origin xyz="0 0 0" rpy="-3.14159 -0 0"/>
      <geometry>
        <mesh filename="file://$(find mbf_description)/meshes/shoulder.stl"/>
      </geometry>
      <material name="shoulder_material">
        <color rgba="0.74902 0.74902 0.74902 1"/>
      </material>
    </visual>
    <collision>
      <origin xyz="0 0 0" rpy="-3.14159 -0 0"/>
      <geometry>
        <mesh filename="file://$(find mbf_description)/meshes/shoulder.stl"/>
      </geometry>
    </collision>
  </link>
  <!-- Link hip -->
  <link name="fl_hip_link">
    <inertial>
      <origin xyz="-0.000800701 -0.0108187 -0.0228388" rpy="0 0 0"/>
      <mass value="0.6"/>
      <inertia ixx="0.00131344" ixy="4.78193e-06" ixz="-8.51185e-06" iyy="0.00134942" iyz="0.000181322" izz="0.000412562"/>
    </inertial>
    <!-- Part hip -->
    <visual>
      <origin xyz="0 -0 -0" rpy="0 -0 1.5708"/>
      <geometry>
        <mesh filename="file://$(find mbf_description)/meshes/hip.stl"/>
      </geometry>
      <material name="hip_material">
        <color rgba="0.74902 0.74902 0.74902 1"/>
      </material>
    </visual>
    <collision>
      <origin xyz="0 -0 -0" rpy="0 -0 1.5708"/>
      <geometry>
        <mesh filename="file://$(find mbf_description)/meshes/hip.stl"/>
      </geometry>
    </collision>
  </link>
  <!-- Link knee -->
  <link name="fl_knee_link">
    <inertial>
      <origin xyz="0.000101397 0.000101309 -0.0636801" rpy="0 0 0"/>
      <mass value="0.15"/>
      <inertia ixx="0.000316741" ixy="1.541e-09" ixz="7.15036e-07" iyy="0.000318933" iyz="-1.05574e-06" izz="1.8258e-05"/>
    </inertial>
    <!-- Part knee -->
    <visual>
      <origin xyz="0 0 -0" rpy="0 -0 -1.5708"/>
      <geometry>
        <mesh filename="file://$(find mbf_description)/meshes/knee.stl"/>
      </geometry>
      <material name="knee_material">
        <color rgba="0.615686 0.811765 0.929412 1"/>
      </material>
    </visual>
    <collision>
      <origin xyz="0 0 -0" rpy="0 -0 -1.5708"/>
      <geometry>
        <mesh filename="file://$(find mbf_description)/meshes/knee.stl"/>
      </geometry>
    </collision>
  </link>
  <!-- Link feet -->
  <link name="fl_feet_link">
    <inertial>
      <origin xyz="0 -0 0" rpy="0 0 0"/>
      <mass value="0.025"/>
      <inertia ixx="4e-06" ixy="0" ixz="0" iyy="4e-06" iyz="0" izz="4e-06"/>
    </inertial>
    <!-- Part feet -->
    <visual>
      <origin xyz="0 0 0" rpy="0 -0 -0"/>
      <geometry>
        <mesh filename="file://$(find mbf_description)/meshes/feet.stl"/>
      </geometry>
      <material name="feet_material">
        <color rgba="0.615686 0.811765 0.929412 1"/>
      </material>
    </visual>
    <collision>
      <origin xyz="0 0 0" rpy="0 -0 -0"/>
      <geometry>
        <mesh filename="file://$(find mbf_description)/meshes/feet.stl"/>
      </geometry>
    </collision>
  </link>
  <!-- Joint from knee to feet -->
  <joint name="fl_feet_joint" type="fixed">
    <origin xyz="-0.000288395 -0 -0.148233" rpy="-0 -0 -0"/>
    <parent link="fl_knee_link"/>
    <child link="fl_feet_link"/>
    <axis xyz="0 0 1"/>
    <limit effort="10" velocity="10"/>
  </joint>
  <!-- Joint from hip to knee -->
  <joint name="fl_knee_joint" type="revolute">
    <origin xyz="0 0 -0.12" rpy="0 0 0"/>
    <parent link="fl_hip_link"/>
    <child link="fl_knee_link"/>
    <axis xyz="0 1 0"/>
    <limit effort="10" velocity="10" upper="0" lower="-2.5"/>
  </joint>
  <!-- Joint from shoulder to hip -->
  <joint name="fl_hip_joint" type="revolute">
    <origin xyz="0 0.081 -0" rpy="0 -0 -0"/>
    <parent link="fl_shoulder_link"/>
    <child link="fl_hip_link"/>
    <axis xyz="0 1 0"/>
    <limit effort="10" velocity="10" upper="2.5" lower="-2.5"/>
  </joint>
  <!-- Joint from chassis to shoulder -->
  <joint name="fl_shoulder_joint" type="revolute">
    <origin xyz="0.1695 0.045 0" rpy="0 0 0"/>
    <parent link="chassis"/>
    <child link="fl_shoulder_link"/>
    <axis xyz="1 0 0"/>
    <limit effort="10" velocity="10" lower="-2.0" upper="2.0"/>
  </joint>
  <!-- Link shoulder_2 -->
  <link name="fr_shoulder_link">
    <inertial>
      <origin xyz="-0.00572995 -0.00737753 1.10852e-06" rpy="0 0 0"/>
      <mass value="0.4"/>
      <inertia ixx="0.000212246" ixy="1.68406e-05" ixz="1.402e-08" iyy="0.000383001" iyz="-2.6453e-08" izz="0.000318608"/>
    </inertial>
    <!-- Part shoulder_2 -->
    <visual>
      <origin xyz="0 0 -0" rpy="-0 0 -0"/>
      <geometry>
        <mesh filename="file://$(find mbf_description)/meshes/shoulder.stl"/>
      </geometry>
      <material name="shoulder_2_material">
        <color rgba="0.74902 0.74902 0.74902 1"/>
      </material>
    </visual>
    <collision>
      <origin xyz="0 0 -0" rpy="-0 0 -0"/>
      <geometry>
        <mesh filename="file://$(find mbf_description)/meshes/shoulder.stl"/>
      </geometry>
    </collision>
  </link>
  <!-- Link hip_2 -->
  <link name="fr_hip_link">
    <inertial>
      <origin xyz="0.000800701 0.0108187 -0.0228388" rpy="0 0 0"/>
      <mass value="0.6"/>
      <inertia ixx="0.00131344" ixy="4.78193e-06" ixz="8.51185e-06" iyy="0.00134942" iyz="-0.000181322" izz="0.000412562"/>
    </inertial>
    <!-- Part hip_2 -->
    <visual>
      <origin xyz="0 0 -0" rpy="0 -0 -1.5708"/>
      <geometry>
        <mesh filename="file://$(find mbf_description)/meshes/hip.stl"/>
      </geometry>
      <material name="hip_2_material">
        <color rgba="0.74902 0.74902 0.74902 1"/>
      </material>
    </visual>
    <collision>
      <origin xyz="0 0 -0" rpy="0 -0 -1.5708"/>
      <geometry>
        <mesh filename="file://$(find mbf_description)/meshes/hip.stl"/>
      </geometry>
    </collision>
  </link>
  <!-- Link knee_2 -->
  <link name="fr_knee_link">
    <inertial>
      <origin xyz="0.000101397 0.000101309 -0.0636801" rpy="0 0 0"/>
      <mass value="0.15"/>
      <inertia ixx="0.000316741" ixy="1.541e-09" ixz="7.15036e-07" iyy="0.000318933" iyz="-1.05574e-06" izz="1.8258e-05"/>
    </inertial>
    <!-- Part knee_2 -->
    <visual>
      <origin xyz="0 0 -0" rpy="0 -0 -1.5708"/>
      <geometry>
        <mesh filename="file://$(find mbf_description)/meshes/knee.stl"/>
      </geometry>
      <material name="knee_2_material">
        <color rgba="0.615686 0.811765 0.929412 1"/>
      </material>
    </visual>
    <collision>
      <origin xyz="0 0 -0" rpy="0 -0 -1.5708"/>
      <geometry>
        <mesh filename="file://$(find mbf_description)/meshes/knee.stl"/>
      </geometry>
    </collision>
  </link>
  <!-- Link feet_2 -->
  <link name="fr_feet_link">
    <inertial>
      <origin xyz="0 0 0" rpy="0 0 0"/>
      <mass value="0.025"/>
      <inertia ixx="4e-06" ixy="0" ixz="0" iyy="4e-06" iyz="0" izz="4e-06"/>
    </inertial>
    <!-- Part feet_2 -->
    <visual>
      <origin xyz="0 0 0" rpy="0 -0 0"/>
      <geometry>
        <mesh filename="file://$(find mbf_description)/meshes/feet.stl"/>
      </geometry>
      <material name="feet_2_material">
        <color rgba="0.615686 0.811765 0.929412 1"/>
      </material>
    </visual>
    <collision>
      <origin xyz="0 0 0" rpy="0 -0 0"/>
      <geometry>
        <mesh filename="file://$(find mbf_description)/meshes/feet.stl"/>
      </geometry>
    </collision>
  </link>
  <!-- Joint from knee_2 to feet_2 -->
  <joint name="fr_feet_joint" type="fixed">
    <origin xyz="-0.000288395 -0 -0.148233" rpy="-0 -0 -0"/>
    <parent link="fr_knee_link"/>
    <child link="fr_feet_link"/>
    <axis xyz="0 0 1"/>
    <limit effort="10" velocity="10"/>
  </joint>
  <!-- Joint from hip_2 to knee_2 -->
  <joint name="fr_knee_joint" type="revolute">
    <origin xyz="0 0 -0.12" rpy="0 -0 -0"/>
    <parent link="fr_hip_link"/>
    <child link="fr_knee_link"/>
    <axis xyz="0 1 0"/>
    <limit effort="10" velocity="10" upper="0" lower="-2.5"/>
  </joint>
  <!-- Joint from shoulder_2 to hip_2 -->
  <joint name="fr_hip_joint" type="revolute">
    <origin xyz="0 -0.081 0" rpy="-0 -0 0"/>
    <parent link="fr_shoulder_link"/>
    <child link="fr_hip_link"/>
    <axis xyz="0 1 0"/>
    <limit effort="10" velocity="10" upper="2.5" lower="-2.5"/>
  </joint>
  <!-- Joint from chassis to shoulder_2 -->
  <joint name="fr_shoulder_joint" type="revolute">
    <origin xyz="0.1695 -0.045 0" rpy="0 0 -0"/>
    <parent link="chassis"/>
    <child link="fr_shoulder_link"/>
    <axis xyz="1 0 0"/>
    <limit effort="10" velocity="10" lower="-2.0" upper="2.0"/>
  </joint>
  <!-- Link shoulder_3 -->
  <link name="rl_shoulder_link">
    <inertial>
      <origin xyz="0.00572995 0.00737753 1.10852e-06" rpy="0 0 0"/>
      <mass value="0.4"/>
      <inertia ixx="0.000212246" ixy="1.68406e-05" ixz="-1.402e-08" iyy="0.000383001" iyz="2.6453e-08" izz="0.000318608"/>
    </inertial>
    <!-- Part shoulder_3 -->
    <visual>
      <origin xyz="0 -0 -0" rpy="-0 0 3.14159"/>
      <geometry>
        <mesh filename="file://$(find mbf_description)/meshes/shoulder.stl"/>
      </geometry>
      <material name="shoulder_3_material">
        <color rgba="0.74902 0.74902 0.74902 1"/>
      </material>
    </visual>
    <collision>
      <origin xyz="0 -0 -0" rpy="-0 0 3.14159"/>
      <geometry>
        <mesh filename="file://$(find mbf_description)/meshes/shoulder.stl"/>
      </geometry>
    </collision>
  </link>
  <!-- Link hip_3 -->
  <link name="rl_hip_link">
    <inertial>
      <origin xyz="-0.000800701 -0.0108187 -0.0228388" rpy="0 0 0"/>
      <mass value="0.6"/>
      <inertia ixx="0.00131344" ixy="4.78193e-06" ixz="-8.51185e-06" iyy="0.00134942" iyz="0.000181322" izz="0.000412562"/>
    </inertial>
    <!-- Part hip_3 -->
    <visual>
      <origin xyz="0 -0 -0" rpy="-0 -0 1.5708"/>
      <geometry>
        <mesh filename="file://$(find mbf_description)/meshes/hip.stl"/>
      </geometry>
      <material name="hip_3_material">
        <color rgba="0.74902 0.74902 0.74902 1"/>
      </material>
    </visual>
    <collision>
      <origin xyz="0 -0 -0" rpy="-0 -0 1.5708"/>
      <geometry>
        <mesh filename="file://$(find mbf_description)/meshes/hip.stl"/>
      </geometry>
    </collision>
  </link>
  <!-- Link knee_3 -->
  <link name="rl_knee_link">
    <inertial>
      <origin xyz="0.000101397 0.000101309 -0.0636801" rpy="0 0 0"/>
      <mass value="0.15"/>
      <inertia ixx="0.000316741" ixy="1.541e-09" ixz="7.15036e-07" iyy="0.000318933" iyz="-1.05574e-06" izz="1.8258e-05"/>
    </inertial>
    <!-- Part knee_3 -->
    <visual>
      <origin xyz="0 0 -0" rpy="-0 -0 -1.5708"/>
      <geometry>
        <mesh filename="file://$(find mbf_description)/meshes/knee.stl"/>
      </geometry>
      <material name="knee_3_material">
        <color rgba="0.615686 0.811765 0.929412 1"/>
      </material>
    </visual>
    <collision>
      <origin xyz="0 0 -0" rpy="-0 -0 -1.5708"/>
      <geometry>
        <mesh filename="file://$(find mbf_description)/meshes/knee.stl"/>
      </geometry>
    </collision>
  </link>
  <!-- Link feet_3 -->
  <link name="rl_feet_link">
    <inertial>
      <origin xyz="0 0 0" rpy="0 0 0"/>
      <mass value="0.025"/>
      <inertia ixx="4e-06" ixy="0" ixz="0" iyy="4e-06" iyz="-0" izz="4e-06"/>
    </inertial>
    <!-- Part feet_3 -->
    <visual>
      <origin xyz="0 0 0" rpy="-0 0 0"/>
      <geometry>
        <mesh filename="file://$(find mbf_description)/meshes/feet.stl"/>
      </geometry>
      <material name="feet_3_material">
        <color rgba="0.615686 0.811765 0.929412 1"/>
      </material>
    </visual>
    <collision>
      <origin xyz="0 0 0" rpy="-0 0 0"/>
      <geometry>
        <mesh filename="file://$(find mbf_description)/meshes/feet.stl"/>
      </geometry>
    </collision>
  </link>
  <!-- Joint from knee_3 to feet_3 -->
  <joint name="rl_feet_joint" type="fixed">
    <origin xyz="-0.000288395 -0 -0.148233" rpy="-0 0 -0"/>
    <parent link="rl_knee_link"/>
    <child link="rl_feet_link"/>
    <axis xyz="0 0 1"/>
    <limit effort="10" velocity="10"/>
  </joint>
  <!-- Joint from hip_3 to knee_3 -->
  <joint name="rl_knee_joint" type="revolute">
    <origin xyz="0 0 -0.12" rpy="0 -0 -0"/>
    <parent link="rl_hip_link"/>
    <child link="rl_knee_link"/>
    <axis xyz="0 1 0"/>
    <limit effort="10" velocity="10" upper="0" lower="-2.5"/>
  </joint>
  <!-- Joint from shoulder_3 to hip_3 -->
  <joint name="rl_hip_joint" type="revolute">
    <origin xyz="0 0.081 -0" rpy="0 -0 0"/>
    <parent link="rl_shoulder_link"/>
    <child link="rl_hip_link"/>
    <axis xyz="0 1 0"/>
    <limit effort="10" velocity="10" upper="2.5" lower="-2.5"/>
  </joint>
  <!-- Joint from chassis to shoulder_3 -->
  <joint name="rl_shoulder_joint" type="revolute">
    <origin xyz="-0.1695 0.045 0" rpy="0 -0 0"/>
    <parent link="chassis"/>
    <child link="rl_shoulder_link"/>
    <axis xyz="1 0 0"/>
    <limit effort="10" velocity="10" lower="-2.0" upper="2.0"/>
  </joint>
  <!-- Link shoulder_4 -->
  <link name="rr_shoulder_link">
    <inertial>
      <origin xyz="0.00572995 -0.00737753 -1.10852e-06" rpy="0 0 0"/>
      <mass value="0.4"/>
      <inertia ixx="0.000212246" ixy="-1.68406e-05" ixz="1.402e-08" iyy="0.000383001" iyz="2.6453e-08" izz="0.000318608"/>
    </inertial>
    <!-- Part shoulder_4 -->
    <visual>
      <origin xyz="0 -0 0" rpy="-3.14159 -0 -3.14159"/>
      <geometry>
        <mesh filename="file://$(find mbf_description)/meshes/shoulder.stl"/>
      </geometry>
      <material name="shoulder_4_material">
        <color rgba="0.74902 0.74902 0.74902 1"/>
      </material>
    </visual>
    <collision>
      <origin xyz="0 -0 0" rpy="-3.14159 -0 -3.14159"/>
      <geometry>
        <mesh filename="file://$(find mbf_description)/meshes/shoulder.stl"/>
      </geometry>
    </collision>
  </link>
  <!-- Link hip_4 -->
  <link name="rr_hip_link">
    <inertial>
      <origin xyz="0.000800701 0.0108187 -0.0228388" rpy="0 0 0"/>
      <mass value="0.6"/>
      <inertia ixx="0.00131344" ixy="4.78193e-06" ixz="8.51185e-06" iyy="0.00134942" iyz="-0.000181322" izz="0.000412562"/>
    </inertial>
    <!-- Part hip_4 -->
    <visual>
      <origin xyz="0 0 -0" rpy="0 -0 -1.5708"/>
      <geometry>
        <mesh filename="file://$(find mbf_description)/meshes/hip.stl"/>
      </geometry>
      <material name="hip_4_material">
        <color rgba="0.74902 0.74902 0.74902 1"/>
      </material>
    </visual>
    <collision>
      <origin xyz="0 0 -0" rpy="0 -0 -1.5708"/>
      <geometry>
        <mesh filename="file://$(find mbf_description)/meshes/hip.stl"/>
      </geometry>
    </collision>
  </link>
  <!-- Link knee_4 -->
  <link name="rr_knee_link">
    <inertial>
      <origin xyz="0.000101397 0.000101309 -0.0636801" rpy="0 0 0"/>
      <mass value="0.15"/>
      <inertia ixx="0.000316741" ixy="1.541e-09" ixz="7.15036e-07" iyy="0.000318933" iyz="-1.05574e-06" izz="1.8258e-05"/>
    </inertial>
    <!-- Part knee_4 -->
    <visual>
      <origin xyz="0 0 -0" rpy="0 -0 -1.5708"/>
      <geometry>
        <mesh filename="file://$(find mbf_description)/meshes/knee.stl"/>
      </geometry>
      <material name="knee_4_material">
        <color rgba="0.615686 0.811765 0.929412 1"/>
      </material>
    </visual>
    <collision>
      <origin xyz="0 0 -0" rpy="0 -0 -1.5708"/>
      <geometry>
        <mesh filename="file://$(find mbf_description)/meshes/knee.stl"/>
      </geometry>
    </collision>
  </link>
  <!-- Link feet_4 -->
  <link name="rr_feet_link">
    <inertial>
      <origin xyz="0 0 0" rpy="0 0 0"/>
      <mass value="0.025"/>
      <inertia ixx="4e-06" ixy="0" ixz="-0" iyy="4e-06" iyz="-0" izz="4e-06"/>
    </inertial>
    <!-- Part feet_4 -->
    <visual>
      <origin xyz="0 0 0" rpy="-0 -0 0"/>
      <geometry>
        <mesh filename="file://$(find mbf_description)/meshes/feet.stl"/>
      </geometry>
      <material name="feet_4_material">
        <color rgba="0.615686 0.811765 0.929412 1"/>
      </material>
    </visual>
    <collision>
      <origin xyz="0 0 0" rpy="-0 -0 0"/>
      <geometry>
        <mesh filename="file://$(find mbf_description)/meshes/feet.stl"/>
      </geometry>
    </collision>
  </link>
  <!-- Joint from knee_4 to feet_4 -->
  <joint name="rr_feet_joint" type="fixed">
    <origin xyz="-0.000288395 -0 -0.148233" rpy="-0 -0 -0"/>
    <parent link="rr_knee_link"/>
    <child link="rr_feet_link"/>
    <axis xyz="0 0 1"/>
    <limit effort="10" velocity="10"/>
  </joint>
  <!-- Joint from hip_4 to knee_4 -->
  <joint name="rr_knee_joint" type="revolute">
    <origin xyz="0 0 -0.12" rpy="0 -0 0"/>
    <parent link="rr_hip_link"/>
    <child link="rr_knee_link"/>
    <axis xyz="0 1 0"/>
    <limit effort="10" velocity="10" upper="0" lower="-2.5"/>
  </joint>
  <!-- Joint from shoulder_4 to hip_4 -->
  <joint name="rr_hip_joint" type="revolute">
    <origin xyz="0 -0.081 -0" rpy="0 -0 0"/>
    <parent link="rr_shoulder_link"/>
    <child link="rr_hip_link"/>
    <axis xyz="0 1 0"/>
    <limit effort="10" velocity="10" upper="2.5" lower="-2.5"/>
  </joint>
  <!-- Joint from chassis to shoulder_4 -->
  <joint name="rr_shoulder_joint" type="revolute">
    <origin xyz="-0.1695 -0.045 0" rpy="0 -0 0"/>
    <parent link="chassis"/>
    <child link="rr_shoulder_link"/>
    <axis xyz="1 0 0"/>
    <limit effort="10" velocity="10" lower="-2.0" upper="2.0"/>
  </joint>
</robot>
