<?xml version="1.0" ?>
<!-- =================================================================================== -->
<!-- |    This document was autogenerated by xacro from src/mbf_description/xacro/robot.xacro | -->
<!-- |    EDITING THIS FILE BY HAND IS NOT RECOMMENDED                                 | -->
<!-- =================================================================================== -->
<robot name="mbf">
  <link name="base_link">
    <visual>
      <origin rpy="0 0 0" xyz="0 0 0"/>
      <geometry>
        <box size="0.001 0.001 0.001"/>
      </geometry>
    </visual>
  </link>
  <joint name="floating_base" type="fixed">
    <origin rpy="0 0 0" xyz="0 0 0"/>
    <parent link="base_link"/>
    <child link="chassis"/>
  </joint>
  <link name="chassis">
    <visual>
      <origin rpy="0 0 0" xyz="0 0 0"/>
      <geometry>
        <mesh filename="file:///home/andrew/projects/mbf_ws/install/mbf_description/share/mbf_description/meshes/Chassis.stl" scale="0.001 0.001 0.001"/>
      </geometry>
      <!-- <material name="grey"/> -->
    </visual>
    <collision>
      <origin rpy="0 0 0" xyz="0 0 0"/>
      <geometry>
        <box size="0.233 0.189 0.114"/>
      </geometry>
    </collision>
    <inertial>
      <origin xyz="0 0 0"/>
      <mass value="1.0"/>
      <inertia ixx="0.00405975" ixy="0.0" ixz="0.0" iyy="0.005607083333333334" iyz="0.0" izz="0.007500833333333333"/>
    </inertial>
  </link>
  <joint name="imu_joint" type="fixed">
    <parent link="chassis"/>
    <child link="imu_link"/>
    <origin rpy="0 0 0" xyz="0 0 0"/>
  </joint>
  <link name="imu_link">
    <inertial>
      <mass value="0.001"/>
      <origin rpy="0 0 0" xyz="0 0 0"/>
      <inertia ixx="0.0001" ixy="0" ixz="0" iyy="0.0001" iyz="0" izz="0.0001"/>
    </inertial>
    <visual>
      <origin rpy="0 0 0" xyz="0 0 0"/>
      <geometry>
        <box size="0.001 0.001 0.001"/>
      </geometry>
      <!-- <material name="red"/> -->
    </visual>
    <collision>
      <origin rpy="0 0 0" xyz="0 0 0"/>
      <geometry>
        <box size=".001 .001 .001"/>
      </geometry>
    </collision>
  </link>
  <joint name="fl_shoulder_joint" type="revolute">
    <axis xyz="1 0 0"/>
    <limit effort="10.0" lower="-0.785398" upper="0.785398" velocity="10.0"/>
    <parent link="chassis"/>
    <child link="fl_shoulder_link"/>
    <origin rpy="0 0 0" xyz="0.16 0.0425 0"/>
  </joint>
  <link name="fl_shoulder_link">
    <inertial>
      <mass value="0.4"/>
      <origin rpy="0 0 0" xyz="0 0 0"/>
      <inertia ixx="0.00023946666666666667" ixy="0.0" ixz="0.0" iyy="0.00042666666666666667" iyz="0.0" izz="0.00023946666666666667"/>
    </inertial>
    <collision>
      <origin rpy="0 0 0" xyz="0 0 0"/>
      <geometry>
        <mesh filename="file:///home/andrew/projects/mbf_ws/install/mbf_description/share/mbf_description/meshes/Shoulder2Knee.stl" scale="0.001 0.001 0.001"/>
      </geometry>
    </collision>
    <visual>
      <origin rpy="0 0 0" xyz="0 0 0"/>
      <geometry>
        <mesh filename="file:///home/andrew/projects/mbf_ws/install/mbf_description/share/mbf_description/meshes/Shoulder2Knee.stl" scale="0.001 0.001 0.001"/>
      </geometry>
      <material name="black"/>
    </visual>
  </link>
  <joint name="fl_hip_joint" type="revolute">
    <axis xyz="0 1 0"/>
    <limit effort="10.0" lower="-1.5708" upper="1.5708" velocity="10.0"/>
    <parent link="fl_shoulder_link"/>
    <child link="fl_hip_link"/>
    <origin rpy="0 0 0" xyz="0 0.085 0"/>
  </joint>
  <link name="fl_hip_link">
    <inertial>
      <mass value="0.4"/>
      <origin rpy="0 0 0" xyz="0 0 -0.06"/>
      <inertia ixx="0.0005008333333333334" ixy="0.0" ixz="0.0" iyy="0.0005099999999999999" iyz="0.0" izz="5.0833333333333333e-05"/>
    </inertial>
    <collision>
      <origin rpy="0 0 3.141592653589793" xyz="0 -0.0375 0"/>
      <geometry>
        <mesh filename="file:///home/andrew/projects/mbf_ws/install/mbf_description/share/mbf_description/meshes/Hip.stl" scale="0.001 0.001 0.001"/>
      </geometry>
    </collision>
    <visual>
      <origin rpy="0 0 3.141592653589793" xyz="0 -0.0375 0"/>
      <geometry>
        <mesh filename="file:///home/andrew/projects/mbf_ws/install/mbf_description/share/mbf_description/meshes/Hip.stl" scale="0.001 0.001 0.001"/>
      </geometry>
    </visual>
  </link>
  <joint name="fl_knee_joint" type="revolute">
    <axis xyz="0 1 0"/>
    <limit effort="10.0" lower="-2.0944" upper="2.0944" velocity="10.0"/>
    <parent link="fl_hip_link"/>
    <child link="fl_knee_link"/>
    <origin rpy="0 0 0" xyz="0 0 -0.12"/>
  </joint>
  <link name="fl_knee_link">
    <inertial>
      <mass value="0.035"/>
      <origin rpy="0 0 0" xyz="0 0 -0.06"/>
      <inertia ixx="4.382291666666667e-05" ixy="0.0" ixz="0.0" iyy="4.4625e-05" iyz="0.0" izz="4.447916666666667e-06"/>
    </inertial>
    <collision>
      <origin rpy="0 0 0" xyz="0 0 -0.06"/>
      <geometry>
        <box size="0.03 0.025 0.12"/>
      </geometry>
    </collision>
    <visual>
      <origin rpy="0 0 0" xyz="0 0 0"/>
      <geometry>
        <mesh filename="file:///home/andrew/projects/mbf_ws/install/mbf_description/share/mbf_description/meshes/Knee.stl" scale="0.001 0.001 0.001"/>
      </geometry>
    </visual>
  </link>
  <link name="fl_feet_link">
    <inertial>
      <mass value="0.035"/>
      <inertia ixx="4e-06" ixy="0.0" ixz="0.0" iyy="4e-06" iyz="0.0" izz="4e-06"/>
    </inertial>
    <collision>
      <origin rpy="0 0 0" xyz="0 0 0"/>
      <geometry>
        <sphere radius="0.02"/>
      </geometry>
    </collision>
    <visual>
      <origin rpy="0 0 0" xyz="-0.018 0 0"/>
      <geometry>
        <mesh filename="file:///home/andrew/projects/mbf_ws/install/mbf_description/share/mbf_description/meshes/Squashball.stl" scale="0.001 0.001 0.001"/>
      </geometry>
    </visual>
  </link>
  <joint name="fl_feet_joint" type="fixed">
    <parent link="fl_knee_link"/>
    <child link="fl_feet_link"/>
    <origin rpy="0 0 0" xyz="0 0 -0.137"/>
  </joint>
  <joint name="fr_shoulder_joint" type="revolute">
    <axis xyz="1 0 0"/>
    <limit effort="10.0" lower="-0.785398" upper="0.785398" velocity="10.0"/>
    <parent link="chassis"/>
    <child link="fr_shoulder_link"/>
    <origin rpy="0 0 0" xyz="0.16 -0.0425 0"/>
  </joint>
  <link name="fr_shoulder_link">
    <inertial>
      <mass value="0.4"/>
      <origin rpy="0 0 0" xyz="0 0 0"/>
      <inertia ixx="0.00023946666666666667" ixy="0.0" ixz="0.0" iyy="0.00042666666666666667" iyz="0.0" izz="0.00023946666666666667"/>
    </inertial>
    <collision>
      <origin rpy="3.141592653589793 0 0" xyz="0 0 0"/>
      <geometry>
        <mesh filename="file:///home/andrew/projects/mbf_ws/install/mbf_description/share/mbf_description/meshes/Shoulder2Knee.stl" scale="0.001 0.001 0.001"/>
      </geometry>
    </collision>
    <visual>
      <origin rpy="3.141592653589793 0 0" xyz="0 0 0"/>
      <geometry>
        <mesh filename="file:///home/andrew/projects/mbf_ws/install/mbf_description/share/mbf_description/meshes/Shoulder2Knee.stl" scale="0.001 0.001 0.001"/>
      </geometry>
      <material name="black"/>
    </visual>
  </link>
  <joint name="fr_hip_joint" type="revolute">
    <axis xyz="0 1 0"/>
    <limit effort="10.0" lower="-1.5708" upper="1.5708" velocity="10.0"/>
    <parent link="fr_shoulder_link"/>
    <child link="fr_hip_link"/>
    <origin rpy="0 0 0" xyz="0 -0.085 0"/>
  </joint>
  <link name="fr_hip_link">
    <inertial>
      <mass value="0.4"/>
      <origin rpy="0 0 0" xyz="0 0 -0.06"/>
      <inertia ixx="0.0005008333333333334" ixy="0.0" ixz="0.0" iyy="0.0005099999999999999" iyz="0.0" izz="5.0833333333333333e-05"/>
    </inertial>
    <collision>
      <origin rpy="0 0 0" xyz="0 0.0375 0"/>
      <geometry>
        <mesh filename="file:///home/andrew/projects/mbf_ws/install/mbf_description/share/mbf_description/meshes/Hip.stl" scale="0.001 0.001 0.001"/>
      </geometry>
    </collision>
    <visual>
      <origin rpy="0 0 0" xyz="0 0.0375 0"/>
      <geometry>
        <mesh filename="file:///home/andrew/projects/mbf_ws/install/mbf_description/share/mbf_description/meshes/Hip.stl" scale="0.001 0.001 0.001"/>
      </geometry>
    </visual>
  </link>
  <joint name="fr_knee_joint" type="revolute">
    <axis xyz="0 1 0"/>
    <limit effort="10.0" lower="-2.0944" upper="2.0944" velocity="10.0"/>
    <parent link="fr_hip_link"/>
    <child link="fr_knee_link"/>
    <origin rpy="0 0 0" xyz="0 0 -0.12"/>
  </joint>
  <link name="fr_knee_link">
    <inertial>
      <mass value="0.035"/>
      <origin rpy="0 0 0" xyz="0 0 -0.06"/>
      <inertia ixx="4.382291666666667e-05" ixy="0.0" ixz="0.0" iyy="4.4625e-05" iyz="0.0" izz="4.447916666666667e-06"/>
    </inertial>
    <collision>
      <origin rpy="0 0 0" xyz="0 0 -0.06"/>
      <geometry>
        <box size="0.03 0.025 0.12"/>
      </geometry>
    </collision>
    <visual>
      <origin rpy="0 0 0" xyz="0 0 0"/>
      <geometry>
        <mesh filename="file:///home/andrew/projects/mbf_ws/install/mbf_description/share/mbf_description/meshes/Knee.stl" scale="0.001 0.001 0.001"/>
      </geometry>
    </visual>
  </link>
  <link name="fr_feet_link">
    <inertial>
      <mass value="0.035"/>
      <inertia ixx="4e-06" ixy="0.0" ixz="0.0" iyy="4e-06" iyz="0.0" izz="4e-06"/>
    </inertial>
    <collision>
      <origin rpy="0 0 0" xyz="0 0 0"/>
      <geometry>
        <sphere radius="0.02"/>
      </geometry>
    </collision>
    <visual>
      <origin rpy="0 0 0" xyz="-0.018 0 0"/>
      <geometry>
        <mesh filename="file:///home/andrew/projects/mbf_ws/install/mbf_description/share/mbf_description/meshes/Squashball.stl" scale="0.001 0.001 0.001"/>
      </geometry>
    </visual>
  </link>
  <joint name="fr_feet_joint" type="fixed">
    <parent link="fr_knee_link"/>
    <child link="fr_feet_link"/>
    <origin rpy="0 0 0" xyz="0 0 -0.137"/>
  </joint>
  <joint name="rl_shoulder_joint" type="revolute">
    <axis xyz="1 0 0"/>
    <limit effort="10.0" lower="-0.785398" upper="0.785398" velocity="10.0"/>
    <parent link="chassis"/>
    <child link="rl_shoulder_link"/>
    <origin rpy="0 0 0" xyz="-0.16 0.0425 0"/>
  </joint>
  <link name="rl_shoulder_link">
    <inertial>
      <mass value="0.4"/>
      <origin rpy="0 0 0" xyz="0 0 0"/>
      <inertia ixx="0.00023946666666666667" ixy="0.0" ixz="0.0" iyy="0.00042666666666666667" iyz="0.0" izz="0.00023946666666666667"/>
    </inertial>
    <collision>
      <origin rpy="3.141592653589793 0 3.141592653589793" xyz="0 0 0"/>
      <geometry>
        <mesh filename="file:///home/andrew/projects/mbf_ws/install/mbf_description/share/mbf_description/meshes/Shoulder2Knee.stl" scale="0.001 0.001 0.001"/>
      </geometry>
    </collision>
    <visual>
      <origin rpy="3.141592653589793 0 3.141592653589793" xyz="0 0 0"/>
      <geometry>
        <mesh filename="file:///home/andrew/projects/mbf_ws/install/mbf_description/share/mbf_description/meshes/Shoulder2Knee.stl" scale="0.001 0.001 0.001"/>
      </geometry>
      <material name="black"/>
    </visual>
  </link>
  <joint name="rl_hip_joint" type="revolute">
    <axis xyz="0 1 0"/>
    <limit effort="10.0" lower="-1.5708" upper="1.5708" velocity="10.0"/>
    <parent link="rl_shoulder_link"/>
    <child link="rl_hip_link"/>
    <origin rpy="0 0 0" xyz="0 0.085 0"/>
  </joint>
  <link name="rl_hip_link">
    <inertial>
      <mass value="0.4"/>
      <origin rpy="0 0 0" xyz="0 0 -0.06"/>
      <inertia ixx="0.0005008333333333334" ixy="0.0" ixz="0.0" iyy="0.0005099999999999999" iyz="0.0" izz="5.0833333333333333e-05"/>
    </inertial>
    <collision>
      <origin rpy="0 0 3.141592653589793" xyz="0 -0.0375 0"/>
      <geometry>
        <mesh filename="file:///home/andrew/projects/mbf_ws/install/mbf_description/share/mbf_description/meshes/Hip.stl" scale="0.001 0.001 0.001"/>
      </geometry>
    </collision>
    <visual>
      <origin rpy="0 0 3.141592653589793" xyz="0 -0.0375 0"/>
      <geometry>
        <mesh filename="file:///home/andrew/projects/mbf_ws/install/mbf_description/share/mbf_description/meshes/Hip.stl" scale="0.001 0.001 0.001"/>
      </geometry>
    </visual>
  </link>
  <joint name="rl_knee_joint" type="revolute">
    <axis xyz="0 1 0"/>
    <limit effort="10.0" lower="-2.0944" upper="2.0944" velocity="10.0"/>
    <parent link="rl_hip_link"/>
    <child link="rl_knee_link"/>
    <origin rpy="0 0 0" xyz="0 0 -0.12"/>
  </joint>
  <link name="rl_knee_link">
    <inertial>
      <mass value="0.035"/>
      <origin rpy="0 0 0" xyz="0 0 -0.06"/>
      <inertia ixx="4.382291666666667e-05" ixy="0.0" ixz="0.0" iyy="4.4625e-05" iyz="0.0" izz="4.447916666666667e-06"/>
    </inertial>
    <collision>
      <origin rpy="0 0 0" xyz="0 0 -0.06"/>
      <geometry>
        <box size="0.03 0.025 0.12"/>
      </geometry>
    </collision>
    <visual>
      <origin rpy="0 0 0" xyz="0 0 0"/>
      <geometry>
        <mesh filename="file:///home/andrew/projects/mbf_ws/install/mbf_description/share/mbf_description/meshes/Knee.stl" scale="0.001 0.001 0.001"/>
      </geometry>
    </visual>
  </link>
  <link name="rl_feet_link">
    <inertial>
      <mass value="0.035"/>
      <inertia ixx="4e-06" ixy="0.0" ixz="0.0" iyy="4e-06" iyz="0.0" izz="4e-06"/>
    </inertial>
    <collision>
      <origin rpy="0 0 0" xyz="0 0 0"/>
      <geometry>
        <sphere radius="0.02"/>
      </geometry>
    </collision>
    <visual>
      <origin rpy="0 0 0" xyz="-0.018 0 0"/>
      <geometry>
        <mesh filename="file:///home/andrew/projects/mbf_ws/install/mbf_description/share/mbf_description/meshes/Squashball.stl" scale="0.001 0.001 0.001"/>
      </geometry>
    </visual>
  </link>
  <joint name="rl_feet_joint" type="fixed">
    <parent link="rl_knee_link"/>
    <child link="rl_feet_link"/>
    <origin rpy="0 0 0" xyz="0 0 -0.137"/>
  </joint>
  <joint name="rr_shoulder_joint" type="revolute">
    <axis xyz="1 0 0"/>
    <limit effort="10.0" lower="-0.785398" upper="0.785398" velocity="10.0"/>
    <parent link="chassis"/>
    <child link="rr_shoulder_link"/>
    <origin rpy="0 0 0" xyz="-0.16 -0.0425 0"/>
  </joint>
  <link name="rr_shoulder_link">
    <inertial>
      <mass value="0.4"/>
      <origin rpy="0 0 0" xyz="0 0 0"/>
      <inertia ixx="0.00023946666666666667" ixy="0.0" ixz="0.0" iyy="0.00042666666666666667" iyz="0.0" izz="0.00023946666666666667"/>
    </inertial>
    <collision>
      <origin rpy="0 0 3.141592653589793" xyz="0 0 0"/>
      <geometry>
        <mesh filename="file:///home/andrew/projects/mbf_ws/install/mbf_description/share/mbf_description/meshes/Shoulder2Knee.stl" scale="0.001 0.001 0.001"/>
      </geometry>
    </collision>
    <visual>
      <origin rpy="0 0 3.141592653589793" xyz="0 0 0"/>
      <geometry>
        <mesh filename="file:///home/andrew/projects/mbf_ws/install/mbf_description/share/mbf_description/meshes/Shoulder2Knee.stl" scale="0.001 0.001 0.001"/>
      </geometry>
      <material name="black"/>
    </visual>
  </link>
  <joint name="rr_hip_joint" type="revolute">
    <axis xyz="0 1 0"/>
    <limit effort="10.0" lower="-1.5708" upper="1.5708" velocity="10.0"/>
    <parent link="rr_shoulder_link"/>
    <child link="rr_hip_link"/>
    <origin rpy="0 0 0" xyz="0 -0.085 0"/>
  </joint>
  <link name="rr_hip_link">
    <inertial>
      <mass value="0.4"/>
      <origin rpy="0 0 0" xyz="0 0 -0.06"/>
      <inertia ixx="0.0005008333333333334" ixy="0.0" ixz="0.0" iyy="0.0005099999999999999" iyz="0.0" izz="5.0833333333333333e-05"/>
    </inertial>
    <collision>
      <origin rpy="0 0 0" xyz="0 0.0375 0"/>
      <geometry>
        <mesh filename="file:///home/andrew/projects/mbf_ws/install/mbf_description/share/mbf_description/meshes/Hip.stl" scale="0.001 0.001 0.001"/>
      </geometry>
    </collision>
    <visual>
      <origin rpy="0 0 0" xyz="0 0.0375 0"/>
      <geometry>
        <mesh filename="file:///home/andrew/projects/mbf_ws/install/mbf_description/share/mbf_description/meshes/Hip.stl" scale="0.001 0.001 0.001"/>
      </geometry>
    </visual>
  </link>
  <joint name="rr_knee_joint" type="revolute">
    <axis xyz="0 1 0"/>
    <limit effort="10.0" lower="-2.0944" upper="2.0944" velocity="10.0"/>
    <parent link="rr_hip_link"/>
    <child link="rr_knee_link"/>
    <origin rpy="0 0 0" xyz="0 0 -0.12"/>
  </joint>
  <link name="rr_knee_link">
    <inertial>
      <mass value="0.035"/>
      <origin rpy="0 0 0" xyz="0 0 -0.06"/>
      <inertia ixx="4.382291666666667e-05" ixy="0.0" ixz="0.0" iyy="4.4625e-05" iyz="0.0" izz="4.447916666666667e-06"/>
    </inertial>
    <collision>
      <origin rpy="0 0 0" xyz="0 0 -0.06"/>
      <geometry>
        <box size="0.03 0.025 0.12"/>
      </geometry>
    </collision>
    <visual>
      <origin rpy="0 0 0" xyz="0 0 0"/>
      <geometry>
        <mesh filename="file:///home/andrew/projects/mbf_ws/install/mbf_description/share/mbf_description/meshes/Knee.stl" scale="0.001 0.001 0.001"/>
      </geometry>
    </visual>
  </link>
  <link name="rr_feet_link">
    <inertial>
      <mass value="0.035"/>
      <inertia ixx="4e-06" ixy="0.0" ixz="0.0" iyy="4e-06" iyz="0.0" izz="4e-06"/>
    </inertial>
    <collision>
      <origin rpy="0 0 0" xyz="0 0 0"/>
      <geometry>
        <sphere radius="0.02"/>
      </geometry>
    </collision>
    <visual>
      <origin rpy="0 0 0" xyz="-0.018 0 0"/>
      <geometry>
        <mesh filename="file:///home/andrew/projects/mbf_ws/install/mbf_description/share/mbf_description/meshes/Squashball.stl" scale="0.001 0.001 0.001"/>
      </geometry>
    </visual>
  </link>
  <joint name="rr_feet_joint" type="fixed">
    <parent link="rr_knee_link"/>
    <child link="rr_feet_link"/>
    <origin rpy="0 0 0" xyz="0 0 -0.137"/>
  </joint>
</robot>
